Workbook

Sheet Dashboard
A1: HR Analytics Dashboard
A2: Workforce headcount, diversity, tenure, pay and attrition | Sample data | KPI cards respond to the department filter
A3: Department filter: | C3: All | F3: As of: | G3: =Assumptions!$B$3 -> 46295
A5: ACTIVE HEADCOUNT | D5: NEW HIRES (LAST 12M) | G5: EXITS (LAST 12M) | J5: ATTRITION RATE (12M)
A6: =Analysis!$B$3 -> 262 | D6: =COUNTIFS(Employee_Data!$D$2:$D$321,Analysis!$B$1,Employee_Data!$G$2:$G$321,">="&Assumptions!$B$4,Employee_Data!$G$2:$G$321,"<="&Assumptions!$B$3) -> 65 | G6: =COUNTIFS(Employee_Data!$D$2:$D$321,Analysis!$B$1,Employee_Data!$H$2:$H$321,">="&Assumptions!$B$4,Employee_Data!$H$2:$H$321,"<="&Assumptions!$B$3) -> 58 | J6: =IFERROR(G6/AVERAGE(Analysis!$B$2,Analysis!$B$3),0) -> 0.22437137
A8: AVG TENURE (YEARS) | D8: AVG ANNUAL SALARY (INR) | G8: FEMALE REPRESENTATION | J8: AVG PERFORMANCE RATING
A9: =IFERROR(AVERAGEIFS(Employee_Data!$O$2:$O$321,Employee_Data!$D$2:$D$321,Analysis!$B$1,Employee_Data!$M$2:$M$321,"Active"),0) -> 3.7788924 | D9: =IFERROR(AVERAGEIFS(Employee_Data!$K$2:$K$321,Employee_Data!$D$2:$D$321,Analysis!$B$1,Employee_Data!$M$2:$M$321,"Active"),0) -> 795633.59 | G9: =IFERROR(COUNTIFS(Employee_Data!$D$2:$D$321,Analysis!$B$1,Employee_Data!$M$2:$M$321,"Active",Employee_Data!$C$2:$C$321,"Female")/A6,0) -> 0.46564885 | J9: =IFERROR(AVERAGEIFS(Employee_Data!$L$2:$L$321,Employee_Data!$D$2:$D$321,Analysis!$B$1,Employee_Data!$M$2:$M$321,"Active"),0) -> 3.3778626
A11: Key insights
A12: ="• Largest department: "&INDEX(Analysis!$A$7:$A$13,MATCH(MAX(Analysis!$B$7:$B$13),Analysis!$B$7:$B$13,0))&" with "&MAX(Analysis!$B$7:$B$13)&" active employees ("&TEXT(MAX(Analysis!$B$7:$B$13)/Analysis!$B$14,"0%")&" of the workforce)." -> • Largest department: Sales with 52 active employees (20% of the workforce).
A13: ="• Highest attrition: "&INDEX(Analysis!$A$7:$A$13,MATCH(MAX(Analysis!$K$7:$K$13),Analysis!$K$7:$K$13,0))&" at "&TEXT(MAX(Analysis!$K$7:$K$13),"0.0%")&" versus the company average of "&TEXT(Analysis!$K$14,"0.0%")&"." -> • Highest attrition: Customer Support at 38.3% versus the company average of 22.4%.
A14: ="• Largest gender pay gap by job level: "&INDEX(Analysis!$A$37:$A$41,MATCH(MAX(Analysis!$D$37:$D$41),Analysis!$D$37:$D$41,0))&" ("&TEXT(MAX(Analysis!$D$37:$D$41),"0.0%")&" higher average pay for men). Female representation overall is "&TEXT(Analysis!$E$14,"0%")&"." -> • Largest gender pay gap by job level: Director (12.7% higher average pay for men). Female representation overall is 47%.

Sheet Analysis
A1: Dept filter criteria | B1: =IF(Dashboard!$C$3="All","*",Dashboard!$C$3) -> *
A2: Filtered headcount at window start | B2: =COUNTIFS(Employee_Data!$D$2:$D$321,$B$1,Employee_Data!$G$2:$G$321,"<"&Assumptions!$B$4,Employee_Data!$H$2:$H$321,"")+COUNTIFS(Employee_Data!$D$2:$D$321,$B$1,Employee_Data!$G$2:$G$321,"<"&Assumptions!$B$4,Employee_Data!$H$2:$H$321,">="&Assumptions!$B$4) -> 255
A3: Filtered active headcount | B3: =COUNTIFS(Employee_Data!$D$2:$D$321,$B$1,Employee_Data!$M$2:$M$321,"Active") -> 262
A5: Headcount & attrition by department
A6: Department | B6: Active HC | C6: Female | D6: Male | E6: Female % | F6: Avg Salary (INR) | G6: Avg Tenure (yrs) | H6: Exits (12m) | I6: HC at Window Start | J6: Average HC | K6: Attrition % (12m)
A7: Sales | B7: =COUNTIFS(Employee_Data!$D$2:$D$321,$A7,Employee_Data!$M$2:$M$321,"Active") -> 52 | C7: =COUNTIFS(Employee_Data!$D$2:$D$321,$A7,Employee_Data!$M$2:$M$321,"Active",Employee_Data!$C$2:$C$321,"Female") -> 23 | D7: =COUNTIFS(Employee_Data!$D$2:$D$321,$A7,Employee_Data!$M$2:$M$321,"Active",Employee_Data!$C$2:$C$321,"Male") -> 29 | E7: =IFERROR(C7/B7,0) -> 0.44230769 | F7: =IFERROR(AVERAGEIFS(Employee_Data!$K$2:$K$321,Employee_Data!$D$2:$D$321,$A7,Employee_Data!$M$2:$M$321,"Active"),0) -> 831480.77 | G7: =IFERROR(AVERAGEIFS(Employee_Data!$O$2:$O$321,Employee_Data!$D$2:$D$321,$A7,Employee_Data!$M$2:$M$321,"Active"),0) -> 3.4423735 | H7: =COUNTIFS(Employee_Data!$D$2:$D$321,$A7,Employee_Data!$H$2:$H$321,">="&Assumptions!$B$4,Employee_Data!$H$2:$H$321,"<="&Assumptions!$B$3) -> 18 | I7: =COUNTIFS(Employee_Data!$D$2:$D$321,$A7,Employee_Data!$G$2:$G$321,"<"&Assumptions!$B$4,Employee_Data!$H$2:$H$321,"")+COUNTIFS(Employee_Data!$D$2:$D$321,$A7,Employee_Data!$G$2:$G$321,"<"&Assumptions!$B$4,Employee_Data!$H$2:$H$321,">="&Assumptions!$B$4) -> 58 | J7: =AVERAGE(I7,B7) -> 55 | K7: =IFERROR(H7/J7,0) -> 0.32727273
A8: Customer Support | B8: =COUNTIFS(Employee_Data!$D$2:$D$321,$A8,Employee_Data!$M$2:$M$321,"Active") -> 42 | C8: =COUNTIFS(Employee_Data!$D$2:$D$321,$A8,Employee_Data!$M$2:$M$321,"Active",Employee_Data!$C$2:$C$321,"Female") -> 20 | D8: =COUNTIFS(Employee_Data!$D$2:$D$321,$A8,Employee_Data!$M$2:$M$321,"Active",Employee_Data!$C$2:$C$321,"Male") -> 22 | E8: =IFERROR(C8/B8,0) -> 0.47619048 | F8: =IFERROR(AVERAGEIFS(Employee_Data!$K$2:$K$321,Employee_Data!$D$2:$D$321,$A8,Employee_Data!$M$2:$M$321,"Active"),0) -> 450309.52 | G8: =IFERROR(AVERAGEIFS(Employee_Data!$O$2:$O$321,Employee_Data!$D$2:$D$321,$A8,Employee_Data!$M$2:$M$321,"Active"),0) -> 4.4091783 | H8: =COUNTIFS(Employee_Data!$D$2:$D$321,$A8,Employee_Data!$H$2:$H$321,">="&Assumptions!$B$4,Employee_Data!$H$2:$H$321,"<="&Assumptions!$B$3) -> 18 | I8: =COUNTIFS(Employee_Data!$D$2:$D$321,$A8,Employee_Data!$G$2:$G$321,"<"&Assumptions!$B$4,Employee_Data!$H$2:$H$321,"")+COUNTIFS(Employee_Data!$D$2:$D$321,$A8,Employee_Data!$G$2:$G$321,"<"&Assumptions!$B$4,Employee_Data!$H$2:$H$321,">="&Assumptions!$B$4) -> 52 | J8: =AVERAGE(I8,B8) -> 47 | K8: =IFERROR(H8/J8,0) -> 0.38297872
A9: IT | B9: =COUNTIFS(Employee_Data!$D$2:$D$321,$A9,Employee_Data!$M$2:$M$321,"Active") -> 47 | C9: =COUNTIFS(Employee_Data!$D$2:$D$321,$A9,Employee_Data!$M$2:$M$321,"Active",Employee_Data!$C$2:$C$321,"Female") -> 13 | D9: =COUNTIFS(Employee_Data!$D$2:$D$321,$A9,Employee_Data!$M$2:$M$321,"Active",Employee_Data!$C$2:$C$321,"Male") -> 34 | E9: =IFERROR(C9/B9,0) -> 0.27659574 | F9: =IFERROR(AVERAGEIFS(Employee_Data!$K$2:$K$321,Employee_Data!$D$2:$D$321,$A9,Employee_Data!$M$2:$M$321,"Active"),0) -> 1062021.3 | G9: =IFERROR(AVERAGEIFS(Employee_Data!$O$2:$O$321,Employee_Data!$D$2:$D$321,$A9,Employee_Data!$M$2:$M$321,"Active"),0) -> 3.9492624 | H9: =COUNTIFS(Employee_Data!$D$2:$D$321,$A9,Employee_Data!$H$2:$H$321,">="&Assumptions!$B$4,Employee_Data!$H$2:$H$321,"<="&Assumptions!$B$3) -> 8 | I9: =COUNTIFS(Employee_Data!$D$2:$D$321,$A9,Employee_Data!$G$2:$G$321,"<"&Assumptions!$B$4,Employee_Data!$H$2:$H$321,"")+COUNTIFS(Employee_Data!$D$2:$D$321,$A9,Employee_Data!$G$2:$G$321,"<"&Assumptions!$B$4,Employee_Data!$H$2:$H$321,">="&Assumptions!$B$4) -> 45 | J9: =AVERAGE(I9,B9) -> 46 | K9: =IFERROR(H9/J9,0) -> 0.17391304
A10: Operations | B10: =COUNTIFS(Employee_Data!$D$2:$D$321,$A10,Employee_Data!$M$2:$M$321,"Active") -> 44 | C10: =COUNTIFS(Employee_Data!$D$2:$D$321,$A10,Employee_Data!$M$2:$M$321,"Active",Employee_Data!$C$2:$C$321,"Female") -> 15 | D10: =COUNTIFS(Employee_Data!$D$2:$D$321,$A10,Employee_Data!$M$2:$M$321,"Active",Employee_Data!$C$2:$C$321,"Male") -> 29 | E10: =IFERROR(C10/B10,0) -> 0.34090909 | F10: =IFERROR(AVERAGEIFS(Employee_Data!$K$2:$K$321,Employee_Data!$D$2:$D$321,$A10,Employee_Data!$M$2:$M$321,"Active"),0) -> 618159.09 | G10: =IFERROR(AVERAGEIFS(Employee_Data!$O$2:$O$321,Employee_Data!$D$2:$D$321,$A10,Employee_Data!$M$2:$M$321,"Active"),0) -> 3.6008338 | H10: =COUNTIFS(Employee_Data!$D$2:$D$321,$A10,Employee_Data!$H$2:$H$321,">="&Assumptions!$B$4,Employee_Data!$H$2:$H$321,"<="&Assumptions!$B$3) -> 6 | I10: =COUNTIFS(Employee_Data!$D$2:$D$321,$A10,Employee_Data!$G$2:$G$321,"<"&Assumptions!$B$4,Employee_Data!$H$2:$H$321,"")+COUNTIFS(Employee_Data!$D$2:$D$321,$A10,Employee_Data!$G$2:$G$321,"<"&Assumptions!$B$4,Employee_Data!$H$2:$H$321,">="&Assumptions!$B$4) -> 41 | J10: =AVERAGE(I10,B10) -> 42.5 | K10: =IFERROR(H10/J10,0) -> 0.14117647
A11: Finance | B11: =COUNTIFS(Employee_Data!$D$2:$D$321,$A11,Employee_Data!$M$2:$M$321,"Active") -> 28 | C11: =COUNTIFS(Employee_Data!$D$2:$D$321,$A11,Employee_Data!$M$2:$M$321,"Active",Employee_Data!$C$2:$C$321,"Female") -> 18 | D11: =COUNTIFS(Employee_Data!$D$2:$D$321,$A11,Employee_Data!$M$2:$M$321,"Active",Employee_Data!$C$2:$C$321,"Male") -> 10 | E11: =IFERROR(C11/B11,0) -> 0.64285714 | F11: =IFERROR(AVERAGEIFS(Employee_Data!$K$2:$K$321,Employee_Data!$D$2:$D$321,$A11,Employee_Data!$M$2:$M$321,"Active"),0) -> 649750 | G11: =IFERROR(AVERAGEIFS(Employee_Data!$O$2:$O$321,Employee_Data!$D$2:$D$321,$A11,Employee_Data!$M$2:$M$321,"Active"),0) -> 3.9511098 | H11: =COUNTIFS(Employee_Data!$D$2:$D$321,$A11,Employee_Data!$H$2:$H$321,">="&Assumptions!$B$4,Employee_Data!$H$2:$H$321,"<="&Assumptions!$B$3) -> 2 | I11: =COUNTIFS(Employee_Data!$D$2:$D$321,$A11,Employee_Data!$G$2:$G$321,"<"&Assumptions!$B$4,Employee_Data!$H$2:$H$321,"")+COUNTIFS(Employee_Data!$D$2:$D$321,$A11,Employee_Data!$G$2:$G$321,"<"&Assumptions!$B$4,Employee_Data!$H$2:$H$321,">="&Assumptions!$B$4) -> 22 | J11: =AVERAGE(I11,B11) -> 25 | K11: =IFERROR(H11/J11,0) -> 0.08
A12: HR | B12: =COUNTIFS(Employee_Data!$D$2:$D$321,$A12,Employee_Data!$M$2:$M$321,"Active") -> 19 | C12: =COUNTIFS(Employee_Data!$D$2:$D$321,$A12,Employee_Data!$M$2:$M$321,"Active",Employee_Data!$C$2:$C$321,"Female") -> 17 | D12: =COUNTIFS(Employee_Data!$D$2:$D$321,$A12,Employee_Data!$M$2:$M$321,"Active",Employee_Data!$C$2:$C$321,"Male") -> 2 | E12: =IFERROR(C12/B12,0) -> 0.89473684 | F12: =IFERROR(AVERAGEIFS(Employee_Data!$K$2:$K$321,Employee_Data!$D$2:$D$321,$A12,Employee_Data!$M$2:$M$321,"Active"),0) -> 1085052.6 | G12: =IFERROR(AVERAGEIFS(Employee_Data!$O$2:$O$321,Employee_Data!$D$2:$D$321,$A12,Employee_Data!$M$2:$M$321,"Active"),0) -> 4.1613891 | H12: =COUNTIFS(Employee_Data!$D$2:$D$321,$A12,Employee_Data!$H$2:$H$321,">="&Assumptions!$B$4,Employee_Data!$H$2:$H$321,"<="&Assumptions!$B$3) -> 1 | I12: =COUNTIFS(Employee_Data!$D$2:$D$321,$A12,Employee_Data!$G$2:$G$321,"<"&Assumptions!$B$4,Employee_Data!$H$2:$H$321,"")+COUNTIFS(Employee_Data!$D$2:$D$321,$A12,Employee_Data!$G$2:$G$321,"<"&Assumptions!$B$4,Employee_Data!$H$2:$H$321,">="&Assumptions!$B$4) -> 16 | J12: =AVERAGE(I12,B12) -> 17.5 | K12: =IFERROR(H12/J12,0) -> 0.057142857
A13: Marketing | B13: =COUNTIFS(Employee_Data!$D$2:$D$321,$A13,Employee_Data!$M$2:$M$321,"Active") -> 30 | C13: =COUNTIFS(Employee_Data!$D$2:$D$321,$A13,Employee_Data!$M$2:$M$321,"Active",Employee_Data!$C$2:$C$321,"Female") -> 16 | D13: =COUNTIFS(Employee_Data!$D$2:$D$321,$A13,Employee_Data!$M$2:$M$321,"Active",Employee_Data!$C$2:$C$321,"Male") -> 14 | E13: =IFERROR(C13/B13,0) -> 0.53333333 | F13: =IFERROR(AVERAGEIFS(Employee_Data!$K$2:$K$321,Employee_Data!$D$2:$D$321,$A13,Employee_Data!$M$2:$M$321,"Active"),0) -> 1012766.7 | G13: =IFERROR(AVERAGEIFS(Employee_Data!$O$2:$O$321,Employee_Data!$D$2:$D$321,$A13,Employee_Data!$M$2:$M$321,"Active"),0) -> 3.0710472 | H13: =COUNTIFS(Employee_Data!$D$2:$D$321,$A13,Employee_Data!$H$2:$H$321,">="&Assumptions!$B$4,Employee_Data!$H$2:$H$321,"<="&Assumptions!$B$3) -> 5 | I13: =COUNTIFS(Employee_Data!$D$2:$D$321,$A13,Employee_Data!$G$2:$G$321,"<"&Assumptions!$B$4,Employee_Data!$H$2:$H$321,"")+COUNTIFS(Employee_Data!$D$2:$D$321,$A13,Employee_Data!$G$2:$G$321,"<"&Assumptions!$B$4,Employee_Data!$H$2:$H$321,">="&Assumptions!$B$4) -> 21 | J13: =AVERAGE(I13,B13) -> 25.5 | K13: =IFERROR(H13/J13,0) -> 0.19607843
A14: Total | B14: =SUM(B7:B13) -> 262 | C14: =SUM(C7:C13) -> 122 | D14: =SUM(D7:D13) -> 140 | E14: =IFERROR(C14/B14,0) -> 0.46564885 | F14: =IFERROR(AVERAGEIFS(Employee_Data!$K$2:$K$321,Employee_Data!$M$2:$M$321,"Active"),0) -> 795633.59 | G14: =IFERROR(AVERAGEIFS(Employee_Data!$O$2:$O$321,Employee_Data!$M$2:$M$321,"Active"),0) -> 3.7788924 | H14: =SUM(H7:H13) -> 58 | I14: =SUM(I7:I13) -> 255 | J14: =AVERAGE(I14,B14) -> 258.5 | K14: =IFERROR(H14/J14,0) -> 0.22437137
A17: Age distribution (active)
A18: Age Band | B18: Active Employees | C18: % of Total
A19: Under 25 | B19: =COUNTIFS(Employee_Data!$P$2:$P$321,$A19,Employee_Data!$M$2:$M$321,"Active") -> 44 | C19: =IFERROR(B19/SUM(B$19:B$23),0) -> 0.16793893
A20: 25 to 34 | B20: =COUNTIFS(Employee_Data!$P$2:$P$321,$A20,Employee_Data!$M$2:$M$321,"Active") -> 165 | C20: =IFERROR(B20/SUM(B$19:B$23),0) -> 0.62977099
A21: 35 to 44 | B21: =COUNTIFS(Employee_Data!$P$2:$P$321,$A21,Employee_Data!$M$2:$M$321,"Active") -> 48 | C21: =IFERROR(B21/SUM(B$19:B$23),0) -> 0.18320611
A22: 45 to 54 | B22: =COUNTIFS(Employee_Data!$P$2:$P$321,$A22,Employee_Data!$M$2:$M$321,"Active") -> 5 | C22: =IFERROR(B22/SUM(B$19:B$23),0) -> 0.019083969
A23: 55 and above | B23: =COUNTIFS(Employee_Data!$P$2:$P$321,$A23,Employee_Data!$M$2:$M$321,"Active") -> 0 | C23: =IFERROR(B23/SUM(B$19:B$23),0) -> 0
A26: Tenure distribution (active)
A27: Tenure Band | B27: Active Employees | C27: % of Total
A28: Under 1 yr | B28: =COUNTIFS(Employee_Data!$Q$2:$Q$321,$A28,Employee_Data!$M$2:$M$321,"Active") -> 54 | C28: =IFERROR(B28/SUM(B$28:B$32),0) -> 0.20610687
A29: 1 to 3 yrs | B29: =COUNTIFS(Employee_Data!$Q$2:$Q$321,$A29,Employee_Data!$M$2:$M$321,"Active") -> 85 | C29: =IFERROR(B29/SUM(B$28:B$32),0) -> 0.32442748
A30: 3 to 5 yrs | B30: =COUNTIFS(Employee_Data!$Q$2:$Q$321,$A30,Employee_Data!$M$2:$M$321,"Active") -> 52 | C30: =IFERROR(B30/SUM(B$28:B$32),0) -> 0.19847328
A31: 5 to 10 yrs | B31: =COUNTIFS(Employee_Data!$Q$2:$Q$321,$A31,Employee_Data!$M$2:$M$321,"Active") -> 54 | C31: =IFERROR(B31/SUM(B$28:B$32),0) -> 0.20610687
A32: 10+ yrs | B32: =COUNTIFS(Employee_Data!$Q$2:$Q$321,$A32,Employee_Data!$M$2:$M$321,"Active") -> 17 | C32: =IFERROR(B32/SUM(B$28:B$32),0) -> 0.064885496
A35: Average salary by job level and gender (active)
A36: Job Level | B36: Avg Salary - Female | C36: Avg Salary - Male | D36: Gap % (Male over Female)
A37: Entry | B37: =IFERROR(AVERAGEIFS(Employee_Data!$K$2:$K$321,Employee_Data!$E$2:$E$321,$A37,Employee_Data!$C$2:$C$321,"Female",Employee_Data!$M$2:$M$321,"Active"),0) -> 339382.98 | C37: =IFERROR(AVERAGEIFS(Employee_Data!$K$2:$K$321,Employee_Data!$E$2:$E$321,$A37,Employee_Data!$C$2:$C$321,"Male",Employee_Data!$M$2:$M$321,"Active"),0) -> 351973.68 | D37: =IFERROR((C37-B37)/C37,0) -> 0.035771724
A38: Associate | B38: =IFERROR(AVERAGEIFS(Employee_Data!$K$2:$K$321,Employee_Data!$E$2:$E$321,$A38,Employee_Data!$C$2:$C$321,"Female",Employee_Data!$M$2:$M$321,"Active"),0) -> 546285.71 | C38: =IFERROR(AVERAGEIFS(Employee_Data!$K$2:$K$321,Employee_Data!$E$2:$E$321,$A38,Employee_Data!$C$2:$C$321,"Male",Employee_Data!$M$2:$M$321,"Active"),0) -> 541863.64 | D38: =IFERROR((C38-B38)/C38,0) -> -0.0081608686
A39: Senior | B39: =IFERROR(AVERAGEIFS(Employee_Data!$K$2:$K$321,Employee_Data!$E$2:$E$321,$A39,Employee_Data!$C$2:$C$321,"Female",Employee_Data!$M$2:$M$321,"Active"),0) -> 895000 | C39: =IFERROR(AVERAGEIFS(Employee_Data!$K$2:$K$321,Employee_Data!$E$2:$E$321,$A39,Employee_Data!$C$2:$C$321,"Male",Employee_Data!$M$2:$M$321,"Active"),0) -> 1008400 | D39: =IFERROR((C39-B39)/C39,0) -> 0.11245537
A40: Manager | B40: =IFERROR(AVERAGEIFS(Employee_Data!$K$2:$K$321,Employee_Data!$E$2:$E$321,$A40,Employee_Data!$C$2:$C$321,"Female",Employee_Data!$M$2:$M$321,"Active"),0) -> 1679000 | C40: =IFERROR(AVERAGEIFS(Employee_Data!$K$2:$K$321,Employee_Data!$E$2:$E$321,$A40,Employee_Data!$C$2:$C$321,"Male",Employee_Data!$M$2:$M$321,"Active"),0) -> 1713571.4 | D40: =IFERROR((C40-B40)/C40,0) -> 0.020175073
A41: Director | B41: =IFERROR(AVERAGEIFS(Employee_Data!$K$2:$K$321,Employee_Data!$E$2:$E$321,$A41,Employee_Data!$C$2:$C$321,"Female",Employee_Data!$M$2:$M$321,"Active"),0) -> 2723500 | C41: =IFERROR(AVERAGEIFS(Employee_Data!$K$2:$K$321,Employee_Data!$E$2:$E$321,$A41,Employee_Data!$C$2:$C$321,"Male",Employee_Data!$M$2:$M$321,"Active"),0) -> 3121428.6 | D41: =IFERROR((C41-B41)/C41,0) -> 0.12748284
A44: Active headcount by location
A45: Location | B45: Active Employees | C45: % of Total
A46: Kolkata | B46: =COUNTIFS(Employee_Data!$F$2:$F$321,$A46,Employee_Data!$M$2:$M$321,"Active") -> 74 | C46: =IFERROR(B46/SUM(B$46:B$50),0) -> 0.28244275
A47: Bengaluru | B47: =COUNTIFS(Employee_Data!$F$2:$F$321,$A47,Employee_Data!$M$2:$M$321,"Active") -> 67 | C47: =IFERROR(B47/SUM(B$46:B$50),0) -> 0.25572519
A48: Mumbai | B48: =COUNTIFS(Employee_Data!$F$2:$F$321,$A48,Employee_Data!$M$2:$M$321,"Active") -> 43 | C48: =IFERROR(B48/SUM(B$46:B$50),0) -> 0.16412214
A49: Delhi NCR | B49: =COUNTIFS(Employee_Data!$F$2:$F$321,$A49,Employee_Data!$M$2:$M$321,"Active") -> 40 | C49: =IFERROR(B49/SUM(B$46:B$50),0) -> 0.15267176
...

Sheet Employee_Data
A1: Emp ID | B1: Name | C1: Gender | D1: Department | E1: Job Level | F1: Location | G1: Hire Date | H1: Exit Date | I1: Exit Reason | J1: Age | K1: Annual Salary (INR) | L1: Performance Rating (1-5) | M1: Status | N1: Exit Type | O1: Tenure (yrs) | P1: Age Band | Q1: Tenure Band | R1: Compa-Ratio
A2: E1001 | B2: Anjali Bose | C2: Female | D2: Customer Support | E2: Entry | F2: Bengaluru | G2: 41182 | J2: 27 | K2: 290000 | L2: 5 | M2: =IF(H2="","Active","Exited") -> Active | N2: =IF(H2="","",IF(OR(I2="Performance Termination",I2="Restructuring"),"Involuntary","Voluntary")) | O2: =(IF(H2="",Assumptions!$B$3,H2)-G2)/365.25 -> 13.998631 | P2: =IF(J2<25,"Under 25",IF(J2<35,"25 to 34",IF(J2<45,"35 to 44",IF(J2<55,"45 to 54","55 and above")))) -> 25 to 34 | Q2: =IF(O2<1,"Under 1 yr",IF(O2<3,"1 to 3 yrs",IF(O2<5,"3 to 5 yrs",IF(O2<10,"5 to 10 yrs","10+ yrs")))) -> 10+ yrs | R2: =K2/INDEX(Assumptions!$B$9:$B$13,MATCH(E2,Assumptions!$A$9:$A$13,0)) -> 0.82857143
A3: E1002 | B3: Suman Sharma | C3: Male | D3: Customer Support | E3: Senior | F3: Kolkata | G3: 41182 | J3: 38 | K3: 833000 | L3: 4 | M3: =IF(H3="","Active","Exited") -> Active | N3: =IF(H3="","",IF(OR(I3="Performance Termination",I3="Restructuring"),"Involuntary","Voluntary")) | O3: =(IF(H3="",Assumptions!$B$3,H3)-G3)/365.25 -> 13.998631 | P3: =IF(J3<25,"Under 25",IF(J3<35,"25 to 34",IF(J3<45,"35 to 44",IF(J3<55,"45 to 54","55 and above")))) -> 35 to 44 | Q3: =IF(O3<1,"Under 1 yr",IF(O3<3,"1 to 3 yrs",IF(O3<5,"3 to 5 yrs",IF(O3<10,"5 to 10 yrs","10+ yrs")))) -> 10+ yrs | R3: =K3/INDEX(Assumptions!$B$9:$B$13,MATCH(E3,Assumptions!$A$9:$A$13,0)) -> 0.87684211
A4: E1003 | B4: Meera Iyer | C4: Female | D4: IT | E4: Associate | F4: Kolkata | G4: 41182 | J4: 31 | K4: 685000 | L4: 4 | M4: =IF(H4="","Active","Exited") -> Active | N4: =IF(H4="","",IF(OR(I4="Performance Termination",I4="Restructuring"),"Involuntary","Voluntary")) | O4: =(IF(H4="",Assumptions!$B$3,H4)-G4)/365.25 -> 13.998631 | P4: =IF(J4<25,"Under 25",IF(J4<35,"25 to 34",IF(J4<45,"35 to 44",IF(J4<55,"45 to 54","55 and above")))) -> 25 to 34 | Q4: =IF(O4<1,"Under 1 yr",IF(O4<3,"1 to 3 yrs",IF(O4<5,"3 to 5 yrs",IF(O4<10,"5 to 10 yrs","10+ yrs")))) -> 10+ yrs | R4: =K4/INDEX(Assumptions!$B$9:$B$13,MATCH(E4,Assumptions!$A$9:$A$13,0)) -> 1.2454545
A5: E1004 | B5: Karan Mukherjee | C5: Male | D5: IT | E5: Entry | F5: Delhi NCR | G5: 41182 | J5: 28 | K5: 423000 | L5: 4 | M5: =IF(H5="","Active","Exited") -> Active | N5: =IF(H5="","",IF(OR(I5="Performance Termination",I5="Restructuring"),"Involuntary","Voluntary")) | O5: =(IF(H5="",Assumptions!$B$3,H5)-G5)/365.25 -> 13.998631 | P5: =IF(J5<25,"Under 25",IF(J5<35,"25 to 34",IF(J5<45,"35 to 44",IF(J5<55,"45 to 54","55 and above")))) -> 25 to 34 | Q5: =IF(O5<1,"Under 1 yr",IF(O5<3,"1 to 3 yrs",IF(O5<5,"3 to 5 yrs",IF(O5<10,"5 to 10 yrs","10+ yrs")))) -> 10+ yrs | R5: =K5/INDEX(Assumptions!$B$9:$B$13,MATCH(E5,Assumptions!$A$9:$A$13,0)) -> 1.2085714
A6: E1005 | B6: Pranav Banerjee | C6: Male | D6: IT | E6: Entry | F6: Hyderabad | G6: 41182 | J6: 27 | K6: 419000 | L6: 5 | M6: =IF(H6="","Active","Exited") -> Active | N6: =IF(H6="","",IF(OR(I6="Performance Termination",I6="Restructuring"),"Involuntary","Voluntary")) | O6: =(IF(H6="",Assumptions!$B$3,H6)-G6)/365.25 -> 13.998631 | P6: =IF(J6<25,"Under 25",IF(J6<35,"25 to 34",IF(J6<45,"35 to 44",IF(J6<55,"45 to 54","55 and above")))) -> 25 to 34 | Q6: =IF(O6<1,"Under 1 yr",IF(O6<3,"1 to 3 yrs",IF(O6<5,"3 to 5 yrs",IF(O6<10,"5 to 10 yrs","10+ yrs")))) -> 10+ yrs | R6: =K6/INDEX(Assumptions!$B$9:$B$13,MATCH(E6,Assumptions!$A$9:$A$13,0)) -> 1.1971429
A7: E1006 | B7: Rituparna Verma | C7: Female | D7: Finance | E7: Associate | F7: Hyderabad | G7: 41182 | J7: 33 | K7: 628000 | L7: 2 | M7: =IF(H7="","Active","Exited") -> Active | N7: =IF(H7="","",IF(OR(I7="Performance Termination",I7="Restructuring"),"Involuntary","Voluntary")) | O7: =(IF(H7="",Assumptions!$B$3,H7)-G7)/365.25 -> 13.998631 | P7: =IF(J7<25,"Under 25",IF(J7<35,"25 to 34",IF(J7<45,"35 to 44",IF(J7<55,"45 to 54","55 and above")))) -> 25 to 34 | Q7: =IF(O7<1,"Under 1 yr",IF(O7<3,"1 to 3 yrs",IF(O7<5,"3 to 5 yrs",IF(O7<10,"5 to 10 yrs","10+ yrs")))) -> 10+ yrs | R7: =K7/INDEX(Assumptions!$B$9:$B$13,MATCH(E7,Assumptions!$A$9:$A$13,0)) -> 1.1418182
A8: E1007 | B8: Priya Singh | C8: Female | D8: HR | E8: Entry | F8: Kolkata | G8: 41182 | J8: 26 | K8: 348000 | L8: 1 | M8: =IF(H8="","Active","Exited") -> Active | N8: =IF(H8="","",IF(OR(I8="Performance Termination",I8="Restructuring"),"Involuntary","Voluntary")) | O8: =(IF(H8="",Assumptions!$B$3,H8)-G8)/365.25 -> 13.998631 | P8: =IF(J8<25,"Under 25",IF(J8<35,"25 to 34",IF(J8<45,"35 to 44",IF(J8<55,"45 to 54","55 and above")))) -> 25 to 34 | Q8: =IF(O8<1,"Under 1 yr",IF(O8<3,"1 to 3 yrs",IF(O8<5,"3 to 5 yrs",IF(O8<10,"5 to 10 yrs","10+ yrs")))) -> 10+ yrs | R8: =K8/INDEX(Assumptions!$B$9:$B$13,MATCH(E8,Assumptions!$A$9:$A$13,0)) -> 0.99428571
A9: E1008 | B9: Vivek Patel | C9: Male | D9: Marketing | E9: Senior | F9: Bengaluru | G9: 41182 | J9: 38 | K9: 931000 | L9: 3 | M9: =IF(H9="","Active","Exited") -> Active | N9: =IF(H9="","",IF(OR(I9="Performance Termination",I9="Restructuring"),"Involuntary","Voluntary")) | O9: =(IF(H9="",Assumptions!$B$3,H9)-G9)/365.25 -> 13.998631 | P9: =IF(J9<25,"Under 25",IF(J9<35,"25 to 34",IF(J9<45,"35 to 44",IF(J9<55,"45 to 54","55 and above")))) -> 35 to 44 | Q9: =IF(O9<1,"Under 1 yr",IF(O9<3,"1 to 3 yrs",IF(O9<5,"3 to 5 yrs",IF(O9<10,"5 to 10 yrs","10+ yrs")))) -> 10+ yrs | R9: =K9/INDEX(Assumptions!$B$9:$B$13,MATCH(E9,Assumptions!$A$9:$A$13,0)) -> 0.98
A10: E1009 | B10: Anjali Reddy | C10: Female | D10: Sales | E10: Associate | F10: Hyderabad | G10: 41273 | J10: 29 | K10: 555000 | L10: 3 | M10: =IF(H10="","Active","Exited") -> Active | N10: =IF(H10="","",IF(OR(I10="Performance Termination",I10="Restructuring"),"Involuntary","Voluntary")) | O10: =(IF(H10="",Assumptions!$B$3,H10)-G10)/365.25 -> 13.749487 | P10: =IF(J10<25,"Under 25",IF(J10<35,"25 to 34",IF(J10<45,"35 to 44",IF(J10<55,"45 to 54","55 and above")))) -> 25 to 34 | Q10: =IF(O10<1,"Under 1 yr",IF(O10<3,"1 to 3 yrs",IF(O10<5,"3 to 5 yrs",IF(O10<10,"5 to 10 yrs","10+ yrs")))) -> 10+ yrs | R10: =K10/INDEX(Assumptions!$B$9:$B$13,MATCH(E10,Assumptions!$A$9:$A$13,0)) -> 1.0090909
A11: E1010 | B11: Meera Reddy | C11: Female | D11: HR | E11: Manager | F11: Mumbai | G11: 41524 | J11: 36 | K11: 1736000 | L11: 4 | M11: =IF(H11="","Active","Exited") -> Active | N11: =IF(H11="","",IF(OR(I11="Performance Termination",I11="Restructuring"),"Involuntary","Voluntary")) | O11: =(IF(H11="",Assumptions!$B$3,H11)-G11)/365.25 -> 13.062286 | P11: =IF(J11<25,"Under 25",IF(J11<35,"25 to 34",IF(J11<45,"35 to 44",IF(J11<55,"45 to 54","55 and above")))) -> 35 to 44 | Q11: =IF(O11<1,"Under 1 yr",IF(O11<3,"1 to 3 yrs",IF(O11<5,"3 to 5 yrs",IF(O11<10,"5 to 10 yrs","10+ yrs")))) -> 10+ yrs | R11: =K11/INDEX(Assumptions!$B$9:$B$13,MATCH(E11,Assumptions!$A$9:$A$13,0)) -> 1.0521212
A12: E1011 | B12: Moumita Singh | C12: Female | D12: Finance | E12: Entry | F12: Mumbai | G12: 41588 | J12: 26 | K12: 347000 | L12: 3 | M12: =IF(H12="","Active","Exited") -> Active | N12: =IF(H12="","",IF(OR(I12="Performance Termination",I12="Restructuring"),"Involuntary","Voluntary")) | O12: =(IF(H12="",Assumptions!$B$3,H12)-G12)/365.25 -> 12.887064 | P12: =IF(J12<25,"Under 25",IF(J12<35,"25 to 34",IF(J12<45,"35 to 44",IF(J12<55,"45 to 54","55 and above")))) -> 25 to 34 | Q12: =IF(O12<1,"Under 1 yr",IF(O12<3,"1 to 3 yrs",IF(O12<5,"3 to 5 yrs",IF(O12<10,"5 to 10 yrs","10+ yrs")))) -> 10+ yrs | R12: =K12/INDEX(Assumptions!$B$9:$B$13,MATCH(E12,Assumptions!$A$9:$A$13,0)) -> 0.99142857
A13: E1012 | B13: Abhishek Khan | C13: Male | D13: Operations | E13: Entry | F13: Kolkata | G13: 42028 | J13: 26 | K13: 360000 | L13: 4 | M13: =IF(H13="","Active","Exited") -> Active | N13: =IF(H13="","",IF(OR(I13="Performance Termination",I13="Restructuring"),"Involuntary","Voluntary")) | O13: =(IF(H13="",Assumptions!$B$3,H13)-G13)/365.25 -> 11.682409 | P13: =IF(J13<25,"Under 25",IF(J13<35,"25 to 34",IF(J13<45,"35 to 44",IF(J13<55,"45 to 54","55 and above")))) -> 25 to 34 | Q13: =IF(O13<1,"Under 1 yr",IF(O13<3,"1 to 3 yrs",IF(O13<5,"3 to 5 yrs",IF(O13<10,"5 to 10 yrs","10+ yrs")))) -> 10+ yrs | R13: =K13/INDEX(Assumptions!$B$9:$B$13,MATCH(E13,Assumptions!$A$9:$A$13,0)) -> 1.0285714
... A29: E1028 | B29: Swati Bose | C29: Female | D29: Operations | E29: Associate | F29: Bengaluru | G29: 43328 | J29: 29 | K29: 532000 | L29: 4 | M29: =IF(H29="","Active","Exited") -> Active | N29: =IF(H29="","",IF(OR(I29="Performance Termination",I29="Restructuring"),"Involuntary","Voluntary")) | O29: =(IF(H29="",Assumptions!$B$3,H29)-G29)/365.25 -> 8.1232033 | P29: =IF(J29<25,"Under 25",IF(J29<35,"25 to 34",IF(J29<45,"35 to 44",IF(J29<55,"45 to 54","55 and above")))) -> 25 to 34 | Q29: =IF(O29<1,"Under 1 yr",IF(O29<3,"1 to 3 yrs",IF(O29<5,"3 to 5 yrs",IF(O29<10,"5 to 10 yrs","10+ yrs")))) -> 5 to 10 yrs | R29: =K29/INDEX(Assumptions!$B$9:$B$13,MATCH(E29,Assumptions!$A$9:$A$13,0)) -> 0.96727273
A30: E1029 | B30: Shreya Reddy | C30: Female | D30: IT | E30: Senior | F30: Mumbai | G30: 43358 | H30: 46139 | I30: Better Compensation | J30: 36 | K30: 1077000 | L30: 3 | M30: =IF(H30="","Active","Exited") -> Exited | N30: =IF(H30="","",IF(OR(I30="Performance Termination",I30="Restructuring"),"Involuntary","Voluntary")) -> Voluntary | O30: =(IF(H30="",Assumptions!$B$3,H30)-G30)/365.25 -> 7.613963 | P30: =IF(J30<25,"Under 25",IF(J30<35,"25 to 34",IF(J30<45,"35 to 44",IF(J30<55,"45 to 54","55 and above")))) -> 35 to 44 | Q30: =IF(O30<1,"Under 1 yr",IF(O30<3,"1 to 3 yrs",IF(O30<5,"3 to 5 yrs",IF(O30<10,"5 to 10 yrs","10+ yrs")))) -> 5 to 10 yrs | R30: =K30/INDEX(Assumptions!$B$9:$B$13,MATCH(E30,Assumptions!$A$9:$A$13,0)) -> 1.1336842
A31: E1030 | B31: Sudipta Roy | C31: Female | D31: Sales | E31: Entry | F31: Kolkata | G31: 43373 | J31: 25 | K31: 331000 | L31: 3 | M31: =IF(H31="","Active","Exited") -> Active | N31: =IF(H31="","",IF(OR(I31="Performance Termination",I31="Restructuring"),"Involuntary","Voluntary")) | O31: =(IF(H31="",Assumptions!$B$3,H31)-G31)/365.25 -> 8 | P31: =IF(J31<25,"Under 25",IF(J31<35,"25 to 34",IF(J31<45,"35 to 44",IF(J31<55,"45 to 54","55 and above")))) -> 25 to 34 | Q31: =IF(O31<1,"Under 1 yr",IF(O31<3,"1 to 3 yrs",IF(O31<5,"3 to 5 yrs",IF(O31<10,"5 to 10 yrs","10+ yrs")))) -> 5 to 10 yrs | R31: =K31/INDEX(Assumptions!$B$9:$B$13,MATCH(E31,Assumptions!$A$9:$A$13,0)) -> 0.94571429
A32: E1031 | B32: Manish Singh | C32: Male | D32: Operations | E32: Entry | F32: Kolkata | G32: 43390 | J32: 27 | K32: 366000 | L32: 4 | M32: =IF(H32="","Active","Exited") -> Active | N32: =IF(H32="","",IF(OR(I32="Performance Termination",I32="Restructuring"),"Involuntary","Voluntary")) | O32: =(IF(H32="",Assumptions!$B$3,H32)-G32)/365.25 -> 7.9534565 | P32: =IF(J32<25,"Under 25",IF(J32<35,"25 to 34",IF(J32<45,"35 to 44",IF(J32<55,"45 to 54","55 and above")))) -> 25 to 34 | Q32: =IF(O32<1,"Under 1 yr",IF(O32<3,"1 to 3 yrs",IF(O32<5,"3 to 5 yrs",IF(O32<10,"5 to 10 yrs","10+ yrs")))) -> 5 to 10 yrs | R32: =K32/INDEX(Assumptions!$B$9:$B$13,MATCH(E32,Assumptions!$A$9:$A$13,0)) -> 1.0457143
A33: E1032 | B33: Sudipta Bose | C33: Female | D33: Finance | E33: Associate | F33: Mumbai | G33: 43429 | J33: 29 | K33: 504000 | L33: 3 | M33: =IF(H33="","Active","Exited") -> Active | N33: =IF(H33="","",IF(OR(I33="Performance Termination",I33="Restructuring"),"Involuntary","Voluntary")) | O33: =(IF(H33="",Assumptions!$B$3,H33)-G33)/365.25 -> 7.8466804 | P33: =IF(J33<25,"Under 25",IF(J33<35,"25 to 34",IF(J33<45,"35 to 44",IF(J33<55,"45 to 54","55 and above")))) -> 25 to 34 | Q33: =IF(O33<1,"Under 1 yr",IF(O33<3,"1 to 3 yrs",IF(O33<5,"3 to 5 yrs",IF(O33<10,"5 to 10 yrs","10+ yrs")))) -> 5 to 10 yrs | R33: =K33/INDEX(Assumptions!$B$9:$B$13,MATCH(E33,Assumptions!$A$9:$A$13,0)) -> 0.91636364
A34: E1033 | B34: Ishita Mukherjee | C34: Female | D34: Operations | E34: Entry | F34: Bengaluru | G34: 43446 | J34: 26 | K34: 355000 | L34: 3 | M34: =IF(H34="","Active","Exited") -> Active | N34: =IF(H34="","",IF(OR(I34="Performance Termination",I34="Restructuring"),"Involuntary","Voluntary")) | O34: =(IF(H34="",Assumptions!$B$3,H34)-G34)/365.25 -> 7.8001369 | P34: =IF(J34<25,"Under 25",IF(J34<35,"25 to 34",IF(J34<45,"35 to 44",IF(J34<55,"45 to 54","55 and above")))) -> 25 to 34 | Q34: =IF(O34<1,"Under 1 yr",IF(O34<3,"1 to 3 yrs",IF(O34<5,"3 to 5 yrs",IF(O34<10,"5 to 10 yrs","10+ yrs")))) -> 5 to 10 yrs | R34: =K34/INDEX(Assumptions!$B$9:$B$13,MATCH(E34,Assumptions!$A$9:$A$13,0)) -> 1.0142857
A35: E1034 | B35: Shreya Banerjee | C35: Female | D35: Finance | E35: Senior | F35: Delhi NCR | G35: 43461 | J35: 35 | K35: 855000 | L35: 1 | M35: =IF(H35="","Active","Exited") -> Active | N35: =IF(H35="","",IF(OR(I35="Performance Termination",I35="Restructuring"),"Involuntary","Voluntary")) | O35: =(IF(H35="",Assumptions!$B$3,H35)-G35)/365.25 -> 7.7590691 | P35: =IF(J35<25,"Under 25",IF(J35<35,"25 to 34",IF(J35<45,"35 to 44",IF(J35<55,"45 to 54","55 and above")))) -> 35 to 44 | Q35: =IF(O35<1,"Under 1 yr",IF(O35<3,"1 to 3 yrs",IF(O35<5,"3 to 5 yrs",IF(O35<10,"5 to 10 yrs","10+ yrs")))) -> 5 to 10 yrs | R35: =K35/INDEX(Assumptions!$B$9:$B$13,MATCH(E35,Assumptions!$A$9:$A$13,0)) -> 0.9
A36: E1035 | B36: Kavya Kapoor | C36: Female | D36: Customer Support | E36: Entry | F36: Bengaluru | G36: 43494 | J36: 26 | K36: 325000 | L36: 5 | M36: =IF(H36="","Active","Exited") -> Active | N36: =IF(H36="","",IF(OR(I36="Performance Termination",I36="Restructuring"),"Involuntary","Voluntary")) | O36: =(IF(H36="",Assumptions!$B$3,H36)-G36)/365.25 -> 7.6687201 | P36: =IF(J36<25,"Under 25",IF(J36<35,"25 to 34",IF(J36<45,"35 to 44",IF(J36<55,"45 to 54","55 and above")))) -> 25 to 34 | Q36: =IF(O36<1,"Under 1 yr",IF(O36<3,"1 to 3 yrs",IF(O36<5,"3 to 5 yrs",IF(O36<10,"5 to 10 yrs","10+ yrs")))) -> 5 to 10 yrs | R36: =K36/INDEX(Assumptions!$B$9:$B$13,MATCH(E36,Assumptions!$A$9:$A$13,0)) -> 0.92857143
A37: E1036 | B37: Moumita Joshi | C37: Female | D37: Operations | E37: Entry | F37: Delhi NCR | G37: 43504 | J37: 27 | K37: 366000 | L37: 3 | M37: =IF(H37="","Active","Exited") -> Active | N37: =IF(H37="","",IF(OR(I37="Performance Termination",I37="Restructuring"),"Involuntary","Voluntary")) | O37: =(IF(H37="",Assumptions!$B$3,H37)-G37)/365.25 -> 7.6413415 | P37: =IF(J37<25,"Under 25",IF(J37<35,"25 to 34",IF(J37<45,"35 to 44",IF(J37<55,"45 to 54","55 and above")))) -> 25 to 34 | Q37: =IF(O37<1,"Under 1 yr",IF(O37<3,"1 to 3 yrs",IF(O37<5,"3 to 5 yrs",IF(O37<10,"5 to 10 yrs","10+ yrs")))) -> 5 to 10 yrs | R37: =K37/INDEX(Assumptions!$B$9:$B$13,MATCH(E37,Assumptions!$A$9:$A$13,0)) -> 1.0457143
A38: E1037 | B38: Rahul Mehta | C38: Male | D38: Marketing | E38: Entry | F38: Hyderabad | G38: 43520 | J38: 27 | K38: 332000 | L38: 3 | M38: =IF(H38="","Active","Exited") -> Active | N38: =IF(H38="","",IF(OR(I38="Performance Termination",I38="Restructuring"),"Involuntary","Voluntary")) | O38: =(IF(H38="",Assumptions!$B$3,H38)-G38)/365.25 -> 7.5975359 | P38: =IF(J38<25,"Under 25",IF(J38<35,"25 to 34",IF(J38<45,"35 to 44",IF(J38<55,"45 to 54","55 and above")))) -> 25 to 34 | Q38: =IF(O38<1,"Under 1 yr",IF(O38<3,"1 to 3 yrs",IF(O38<5,"3 to 5 yrs",IF(O38<10,"5 to 10 yrs","10+ yrs")))) -> 5 to 10 yrs | R38: =K38/INDEX(Assumptions!$B$9:$B$13,MATCH(E38,Assumptions!$A$9:$A$13,0)) -> 0.94857143
A39: E1038 | B39: Kavya Nair | C39: Female | D39: Customer Support | E39: Senior | F39: Kolkata | G39: 43565 | J39: 34 | K39: 834000 | L39: 3 | M39: =IF(H39="","Active","Exited") -> Active | N39: =IF(H39="","",IF(OR(I39="Performance Termination",I39="Restructuring"),"Involuntary","Voluntary")) | O39: =(IF(H39="",Assumptions!$B$3,H39)-G39)/365.25 -> 7.4743326 | P39: =IF(J39<25,"Under 25",IF(J39<35,"25 to 34",IF(J39<45,"35 to 44",IF(J39<55,"45 to 54","55 and above")))) -> 25 to 34 | Q39: =IF(O39<1,"Under 1 yr",IF(O39<3,"1 to 3 yrs",IF(O39<5,"3 to 5 yrs",IF(O39<10,"5 to 10 yrs","10+ yrs")))) -> 5 to 10 yrs | R39: =K39/INDEX(Assumptions!$B$9:$B$13,MATCH(E39,Assumptions!$A$9:$A$13,0)) -> 0.87789474
A40: E1039 | B40: Meera Patel | C40: Female | D40: HR | E40: Manager | F40: Kolkata | G40: 43576 | J40: 40 | K40: 1430000 | L40: 4 | M40: =IF(H40="","Active","Exited") -> Active | N40: =IF(H40="","",IF(OR(I40="Performance Termination",I40="Restructuring"),"Involuntary","Voluntary")) | O40: =(IF(H40="",Assumptions!$B$3,H40)-G40)/365.25 -> 7.4442163 | P40: =IF(J40<25,"Under 25",IF(J40<35,"25 to 34",IF(J40<45,"35 to 44",IF(J40<55,"45 to 54","55 and above")))) -> 35 to 44 | Q40: =IF(O40<1,"Under 1 yr",IF(O40<3,"1 to 3 yrs",IF(O40<5,"3 to 5 yrs",IF(O40<10,"5 to 10 yrs","10+ yrs")))) -> 5 to 10 yrs | R40: =K40/INDEX(Assumptions!$B$9:$B$13,MATCH(E40,Assumptions!$A$9:$A$13,0)) -> 0.86666667
A41: E1040 | B41: Aditi Verma | C41: Female | D41: Marketing | E41: Director | F41: Kolkata | G41: 43578 | J41: 43 | K41: 2899000 | L41: 4 | M41: =IF(H41="","Active","Exited") -> Active | N41: =IF(H41="","",IF(OR(I41="Performance Termination",I41="Restructuring"),"Involuntary","Voluntary")) | O41: =(IF(H41="",Assumptions!$B$3,H41)-G41)/365.25 -> 7.4387406 | P41: =IF(J41<25,"Under 25",IF(J41<35,"25 to 34",IF(J41<45,"35 to 44",IF(J41<55,"45 to 54","55 and above")))) -> 35 to 44 | Q41: =IF(O41<1,"Under 1 yr",IF(O41<3,"1 to 3 yrs",IF(O41<5,"3 to 5 yrs",IF(O41<10,"5 to 10 yrs","10+ yrs")))) -> 5 to 10 yrs | R41: =K41/INDEX(Assumptions!$B$9:$B$13,MATCH(E41,Assumptions!$A$9:$A$13,0)) -> 0.96633333
A42: E1041 | B42: Deepak Reddy | C42: Male | D42: IT | E42: Associate | F42: Kolkata | G42: 43582 | J42: 30 | K42: 681000 | L42: 2 | M42: =IF(H42="","Active","Exited") -> Active | N42: =IF(H42="","",IF(OR(I42="Performance Termination",I42="Restructuring"),"Involuntary","Voluntary")) | O42: =(IF(H42="",Assumptions!$B$3,H42)-G42)/365.25 -> 7.4277892 | P42: =IF(J42<25,"Under 25",IF(J42<35,"25 to 34",IF(J42<45,"35 to 44",IF(J42<55,"45 to 54","55 and above")))) -> 25 to 34 | Q42: =IF(O42<1,"Under 1 yr",IF(O42<3,"1 to 3 yrs",IF(O42<5,"3 to 5 yrs",IF(O42<10,"5 to 10 yrs","10+ yrs")))) -> 5 to 10 yrs | R42: =K42/INDEX(Assumptions!$B$9:$B$13,MATCH(E42,Assumptions!$A$9:$A$13,0)) -> 1.2381818
A43: E1042 | B43: Amit Saha | C43: Male | D43: Finance | E43: Senior | F43: Hyderabad | G43: 43603 | J43: 31 | K43: 1059000 | L43: 3 | M43: =IF(H43="","Active","Exited") -> Active | N43: =IF(H43="","",IF(OR(I43="Performance Termination",I43="Restructuring"),"Involuntary","Voluntary")) | O43: =(IF(H43="",Assumptions!$B$3,H43)-G43)/365.25 -> 7.3702943 | P43: =IF(J43<25,"Under 25",IF(J43<35,"25 to 34",IF(J43<45,"35 to 44",IF(J43<55,"45 to 54","55 and above")))) -> 25 to 34 | Q43: =IF(O43<1,"Under 1 yr",IF(O43<3,"1 to 3 yrs",IF(O43<5,"3 to 5 yrs",IF(O43<10,"5 to 10 yrs","10+ yrs")))) -> 5 to 10 yrs | R43: =K43/INDEX(Assumptions!$B$9:$B$13,MATCH(E43,Assumptions!$A$9:$A$13,0)) -> 1.1147368
A44: E1043 | B44: Debjani Gupta | C44: Female | D44: Customer Support | E44: Senior | F44: Kolkata | G44: 43615 | H44: 46185 | I44: Work-Life Balance | J44: 37 | K44: 872000 | L44: 4 | M44: =IF(H44="","Active","Exited") -> Exited | N44: =IF(H44="","",IF(OR(I44="Performance Termination",I44="Restructuring"),"Involuntary","Voluntary")) -> Voluntary | O44: =(IF(H44="",Assumptions!$B$3,H44)-G44)/365.25 -> 7.0362765 | P44: =IF(J44<25,"Under 25",IF(J44<35,"25 to 34",IF(J44<45,"35 to 44",IF(J44<55,"45 to 54","55 and above")))) -> 35 to 44 | Q44: =IF(O44<1,"Under 1 yr",IF(O44<3,"1 to 3 yrs",IF(O44<5,"3 to 5 yrs",IF(O44<10,"5 to 10 yrs","10+ yrs")))) -> 5 to 10 yrs | R44: =K44/INDEX(Assumptions!$B$9:$B$13,MATCH(E44,Assumptions!$A$9:$A$13,0)) -> 0.91789474
A45: E1044 | B45: Vikram Patel | C45: Male | D45: Marketing | E45: Senior | F45: Bengaluru | G45: 43615 | J45: 35 | K45: 876000 | L45: 3 | M45: =IF(H45="","Active","Exited") -> Active | N45: =IF(H45="","",IF(OR(I45="Performance Termination",I45="Restructuring"),"Involuntary","Voluntary")) | O45: =(IF(H45="",Assumptions!$B$3,H45)-G45)/365.25 -> 7.3374401 | P45: =IF(J45<25,"Under 25",IF(J45<35,"25 to 34",IF(J45<45,"35 to 44",IF(J45<55,"45 to 54","55 and above")))) -> 35 to 44 | Q45: =IF(O45<1,"Under 1 yr",IF(O45<3,"1 to 3 yrs",IF(O45<5,"3 to 5 yrs",IF(O45<10,"5 to 10 yrs","10+ yrs")))) -> 5 to 10 yrs | R45: =K45/INDEX(Assumptions!$B$9:$B$13,MATCH(E45,Assumptions!$A$9:$A$13,0)) -> 0.92210526
A46: E1045 | B46: Anjali Reddy | C46: Female | D46: Customer Support | E46: Entry | F46: Bengaluru | G46: 43634 | H46: 46095 | I46: Work-Life Balance | J46: 26 | K46: 253000 | L46: 3 | M46: =IF(H46="","Active","Exited") -> Exited | N46: =IF(H46="","",IF(OR(I46="Performance Termination",I46="Restructuring"),"Involuntary","Voluntary")) -> Voluntary | O46: =(IF(H46="",Assumptions!$B$3,H46)-G46)/365.25 -> 6.7378508 | P46: =IF(J46<25,"Under 25",IF(J46<35,"25 to 34",IF(J46<45,"35 to 44",IF(J46<55,"45 to 54","55 and above")))) -> 25 to 34 | Q46: =IF(O46<1,"Under 1 yr",IF(O46<3,"1 to 3 yrs",IF(O46<5,"3 to 5 yrs",IF(O46<10,"5 to 10 yrs","10+ yrs")))) -> 5 to 10 yrs | R46: =K46/INDEX(Assumptions!$B$9:$B$13,MATCH(E46,Assumptions!$A$9:$A$13,0)) -> 0.72285714
A47: E1046 | B47: Rohit Khan | C47: Male | D47: Sales | E47: Manager | F47: Kolkata | G47: 43649 | J47: 39 | K47: 1560000 | L47: 4 | M47: =IF(H47="","Active","Exited") -> Active | N47: =IF(H47="","",IF(OR(I47="Performance Termination",I47="Restructuring"),"Involuntary","Voluntary")) | O47: =(IF(H47="",Assumptions!$B$3,H47)-G47)/365.25 -> 7.2443532 | P47: =IF(J47<25,"Under 25",IF(J47<35,"25 to 34",IF(J47<45,"35 to 44",IF(J47<55,"45 to 54","55 and above")))) -> 35 to 44 | Q47: =IF(O47<1,"Under 1 yr",IF(O47<3,"1 to 3 yrs",IF(O47<5,"3 to 5 yrs",IF(O47<10,"5 to 10 yrs","10+ yrs")))) -> 5 to 10 yrs | R47: =K47/INDEX(Assumptions!$B$9:$B$13,MATCH(E47,Assumptions!$A$9:$A$13,0)) -> 0.94545455
A48: E1047 | B48: Rituparna Gupta | C48: Female | D48: Operations | E48: Entry | F48: Bengaluru | G48: 43660 | J48: 25 | K48: 313000 | L48: 3 | M48: =IF(H48="","Active","Exited") -> Active | N48: =IF(H48="","",IF(OR(I48="Performance Termination",I48="Restructuring"),"Involuntary","Voluntary")) | O48: =(IF(H48="",Assumptions!$B$3,H48)-G48)/365.25 -> 7.2142368 | P48: =IF(J48<25,"Under 25",IF(J48<35,"25 to 34",IF(J48<45,"35 to 44",IF(J48<55,"45 to 54","55 and above")))) -> 25 to 34 | Q48: =IF(O48<1,"Under 1 yr",IF(O48<3,"1 to 3 yrs",IF(O48<5,"3 to 5 yrs",IF(O48<10,"5 to 10 yrs","10+ yrs")))) -> 5 to 10 yrs | R48: =K48/INDEX(Assumptions!$B$9:$B$13,MATCH(E48,Assumptions!$A$9:$A$13,0)) -> 0.89428571
A49: E1048 | B49: Sneha Iyer | C49: Female | D49: HR | E49: Associate | F49: Delhi NCR | G49: 43712 | J49: 30 | K49: 517000 | L49: 3 | M49: =IF(H49="","Active","Exited") -> Active | N49: =IF(H49="","",IF(OR(I49="Performance Termination",I49="Restructuring"),"Involuntary","Voluntary")) | O49: =(IF(H49="",Assumptions!$B$3,H49)-G49)/365.25 -> 7.0718686 | P49: =IF(J49<25,"Under 25",IF(J49<35,"25 to 34",IF(J49<45,"35 to 44",IF(J49<55,"45 to 54","55 and above")))) -> 25 to 34 | Q49: =IF(O49<1,"Under 1 yr",IF(O49<3,"1 to 3 yrs",IF(O49<5,"3 to 5 yrs",IF(O49<10,"5 to 10 yrs","10+ yrs")))) -> 5 to 10 yrs | R49: =K49/INDEX(Assumptions!$B$9:$B$13,MATCH(E49,Assumptions!$A$9:$A$13,0)) -> 0.94
A50: E1049 | B50: Abhishek Roy | C50: Male | D50: IT | E50: Associate | F50: Kolkata | G50: 43718 | J50: 29 | K50: 651000 | L50: 4 | M50: =IF(H50="","Active","Exited") -> Active | N50: =IF(H50="","",IF(OR(I50="Performance Termination",I50="Restructuring"),"Involuntary","Voluntary")) | O50: =(IF(H50="",Assumptions!$B$3,H50)-G50)/365.25 -> 7.0554415 | P50: =IF(J50<25,"Under 25",IF(J50<35,"25 to 34",IF(J50<45,"35 to 44",IF(J50<55,"45 to 54","55 and above")))) -> 25 to 34 | Q50: =IF(O50<1,"Under 1 yr",IF(O50<3,"1 to 3 yrs",IF(O50<5,"3 to 5 yrs",IF(O50<10,"5 to 10 yrs","10+ yrs")))) -> 5 to 10 yrs | R50: =K50/INDEX(Assumptions!$B$9:$B$13,MATCH(E50,Assumptions!$A$9:$A$13,0)) -> 1.1836364
A51: E1050 | B51: Isha Sen | C51: Female | D51: Marketing | E51: Manager | F51: Delhi NCR | G51: 43752 | H51: 46223 | I51: Work-Life Balance | J51: 41 | K51: 1687000 | L51: 2 | M51: =IF(H51="","Active","Exited") -> Exited | N51: =IF(H51="","",IF(OR(I51="Performance Termination",I51="Restructuring"),"Involuntary","Voluntary")) -> Voluntary | O51: =(IF(H51="",Assumptions!$B$3,H51)-G51)/365.25 -> 6.7652293 | P51: =IF(J51<25,"Under 25",IF(J51<35,"25 to 34",IF(J51<45,"35 to 44",IF(J51<55,"45 to 54","55 and above")))) -> 35 to 44 | Q51: =IF(O51<1,"Under 1 yr",IF(O51<3,"1 to 3 yrs",IF(O51<5,"3 to 5 yrs",IF(O51<10,"5 to 10 yrs","10+ yrs")))) -> 5 to 10 yrs | R51: =K51/INDEX(Assumptions!$B$9:$B$13,MATCH(E51,Assumptions!$A$9:$A$13,0)) -> 1.0224242
A52: E1051 | B52: Aditi Verma | C52: Female | D52: Sales | E52: Associate | F52: Bengaluru | G52: 43753 | H52: 46246 | I52: Performance Termination | J52: 30 | K52: 519000 | L52: 1 | M52: =IF(H52="","Active","Exited") -> Exited | N52: =IF(H52="","",IF(OR(I52="Performance Termination",I52="Restructuring"),"Involuntary","Voluntary")) -> Involuntary | O52: =(IF(H52="",Assumptions!$B$3,H52)-G52)/365.25 -> 6.825462 | P52: =IF(J52<25,"Under 25",IF(J52<35,"25 to 34",IF(J52<45,"35 to 44",IF(J52<55,"45 to 54","55 and above")))) -> 25 to 34 | Q52: =IF(O52<1,"Under 1 yr",IF(O52<3,"1 to 3 yrs",IF(O52<5,"3 to 5 yrs",IF(O52<10,"5 to 10 yrs","10+ yrs")))) -> 5 to 10 yrs | R52: =K52/INDEX(Assumptions!$B$9:$B$13,MATCH(E52,Assumptions!$A$9:$A$13,0)) -> 0.94363636
A53: E1052 | B53: Siddharth Das | C53: Male | D53: IT | E53: Director | F53: Hyderabad | G53: 43761 | J53: 42 | K53: 3348000 | L53: 4 | M53: =IF(H53="","Active","Exited") -> Active | N53: =IF(H53="","",IF(OR(I53="Performance Termination",I53="Restructuring"),"Involuntary","Voluntary")) | O53: =(IF(H53="",Assumptions!$B$3,H53)-G53)/365.25 -> 6.9377139 | P53: =IF(J53<25,"Under 25",IF(J53<35,"25 to 34",IF(J53<45,"35 to 44",IF(J53<55,"45 to 54","55 and above")))) -> 35 to 44 | Q53: =IF(O53<1,"Under 1 yr",IF(O53<3,"1 to 3 yrs",IF(O53<5,"3 to 5 yrs",IF(O53<10,"5 to 10 yrs","10+ yrs")))) -> 5 to 10 yrs | R53: =K53/INDEX(Assumptions!$B$9:$B$13,MATCH(E53,Assumptions!$A$9:$A$13,0)) -> 1.116
A54: E1053 | B54: Rohit Saha | C54: Male | D54: IT | E54: Entry | F54: Mumbai | G54: 43811 | J54: 26 | K54: 374000 | L54: 5 | M54: =IF(H54="","Active","Exited") -> Active | N54: =IF(H54="","",IF(OR(I54="Performance Termination",I54="Restructuring"),"Involuntary","Voluntary")) | O54: =(IF(H54="",Assumptions!$B$3,H54)-G54)/365.25 -> 6.8008214 | P54: =IF(J54<25,"Under 25",IF(J54<35,"25 to 34",IF(J54<45,"35 to 44",IF(J54<55,"45 to 54","55 and above")))) -> 25 to 34 | Q54: =IF(O54<1,"Under 1 yr",IF(O54<3,"1 to 3 yrs",IF(O54<5,"3 to 5 yrs",IF(O54<10,"5 to 10 yrs","10+ yrs")))) -> 5 to 10 yrs | R54: =K54/INDEX(Assumptions!$B$9:$B$13,MATCH(E54,Assumptions!$A$9:$A$13,0)) -> 1.0685714
A55: E1054 | B55: Sourav Khan | C55: Male | D55: Operations | E55: Associate | F55: Hyderabad | G55: 43864 | J55: 28 | K55: 586000 | L55: 3 | M55: =IF(H55="","Active","Exited") -> Active | N55: =IF(H55="","",IF(OR(I55="Performance Termination",I55="Restructuring"),"Involuntary","Voluntary")) | O55: =(IF(H55="",Assumptions!$B$3,H55)-G55)/365.25 -> 6.6557153 | P55: =IF(J55<25,"Under 25",IF(J55<35,"25 to 34",IF(J55<45,"35 to 44",IF(J55<55,"45 to 54","55 and above")))) -> 25 to 34 | Q55: =IF(O55<1,"Under 1 yr",IF(O55<3,"1 to 3 yrs",IF(O55<5,"3 to 5 yrs",IF(O55<10,"5 to 10 yrs","10+ yrs")))) -> 5 to 10 yrs | R55: =K55/INDEX(Assumptions!$B$9:$B$13,MATCH(E55,Assumptions!$A$9:$A$13,0)) -> 1.0654545
...

Sheet Assumptions
A1: Assumptions & Method
A2: Blue text = editable input | Black = formula | Yellow fill = key assumption
A3: As-of (reporting) date | B3: 46295
A4: 12-month window start | B4: =EOMONTH(B3,-12)+1 -> 45931
A8: Job Level | B8: Salary Midpoint (INR)
A9: Entry | B9: 350000
A10: Associate | B10: 550000
A11: Senior | B11: 950000
A12: Manager | B12: 1650000
A13: Director | B13: 3000000
